Workbook

Sheet Calculator
B2: AERO RESPONSE-SURFACE CALCULATOR
B3: Enter any combination of inputs in the yellow cells. Predicted outputs update automatically using the LINEST quadratic fits.
B5: INPUTS
B6: Variable | C6: Value | D6: Valid Range
B7: Front Track [in] | C7: 8 | D7: 7.4 – 8.6
B8: Rear Track [in] | C8: 8 | D8: 7.4 – 8.6
B9: Yaw Angle [deg] | C9: 0 | D9: 0 – 8
B10: Roll Angle [deg] | C10: 0 | D10: 0 – 1.0
B11: Steer Angle [deg] | C11: 0 | D11: 0 – 25.99
B14: PREDICTED OUTPUTS
B15: Output | C15: Predicted Value | D15: Notes
B16: COP Sprung [% Front] | C16: ='LINEST VARS'!$U$48+'LINEST VARS'!$T$48*($C$7)+'LINEST VARS'!$S$48*($C$8)+'LINEST VARS'!$R$48*($C$9)+'LINEST VARS'!$Q$48*($C$10)+'LINEST VARS'!$P$48*($C$11)+'LINEST VARS'!$O$48*($C$7^2)+'LINEST VARS'!$N$48*($C$8^2)+'LINEST VARS'!$M$48*($C$9^2)+'LINEST VARS'!$L$48*($C$10^2)+'LINEST VARS'!$K$48*($C$11^2)+'LINEST VARS'!$J$48*($C$7*$C$8)+'LINEST VARS'!$I$48*($C$7*$C$9)+'LINEST VARS'!$H$48*($C$7*$C$10)+'LINEST VARS'!$G$48*($C$7*$C$11)+'LINEST VARS'!$F$48*($C$8*$C$9)+'LINEST VARS'!$E$48*($C$8*$C$10)+'LINEST VARS'!$D$48*($C$8*$C$11)+'LINEST VARS'!$C$48*($C$9*$C$10)+'LINEST VARS'!$B$48*($C$9*$C$11)+'LINEST VARS'!$A$48*($C$10*$C$11) -> 370 | D16: from LINEST row 48
B17: COP Unsprung [% Front] | C17: ='LINEST VARS'!$U$50+'LINEST VARS'!$T$50*($C$7)+'LINEST VARS'!$S$50*($C$8)+'LINEST VARS'!$R$50*($C$9)+'LINEST VARS'!$Q$50*($C$10)+'LINEST VARS'!$P$50*($C$11)+'LINEST VARS'!$O$50*($C$7^2)+'LINEST VARS'!$N$50*($C$8^2)+'LINEST VARS'!$M$50*($C$9^2)+'LINEST VARS'!$L$50*($C$10^2)+'LINEST VARS'!$K$50*($C$11^2)+'LINEST VARS'!$J$50*($C$7*$C$8)+'LINEST VARS'!$I$50*($C$7*$C$9)+'LINEST VARS'!$H$50*($C$7*$C$10)+'LINEST VARS'!$G$50*($C$7*$C$11)+'LINEST VARS'!$F$50*($C$8*$C$9)+'LINEST VARS'!$E$50*($C$8*$C$10)+'LINEST VARS'!$D$50*($C$8*$C$11)+'LINEST VARS'!$C$50*($C$9*$C$10)+'LINEST VARS'!$B$50*($C$9*$C$11)+'LINEST VARS'!$A$50*($C$10*$C$11) -> 332 | D17: from LINEST row 50
B18: COP Sprung Height [in] | C18: ='LINEST VARS'!$U$52+'LINEST VARS'!$T$52*($C$7)+'LINEST VARS'!$S$52*($C$8)+'LINEST VARS'!$R$52*($C$9)+'LINEST VARS'!$Q$52*($C$10)+'LINEST VARS'!$P$52*($C$11)+'LINEST VARS'!$O$52*($C$7^2)+'LINEST VARS'!$N$52*($C$8^2)+'LINEST VARS'!$M$52*($C$9^2)+'LINEST VARS'!$L$52*($C$10^2)+'LINEST VARS'!$K$52*($C$11^2)+'LINEST VARS'!$J$52*($C$7*$C$8)+'LINEST VARS'!$I$52*($C$7*$C$9)+'LINEST VARS'!$H$52*($C$7*$C$10)+'LINEST VARS'!$G$52*($C$7*$C$11)+'LINEST VARS'!$F$52*($C$8*$C$9)+'LINEST VARS'!$E$52*($C$8*$C$10)+'LINEST VARS'!$D$52*($C$8*$C$11)+'LINEST VARS'!$C$52*($C$9*$C$10)+'LINEST VARS'!$B$52*($C$9*$C$11)+'LINEST VARS'!$A$52*($C$10*$C$11) -> 4.5 | D18: from LINEST row 52
B19: COP Unsprung Height [in] | C19: ='LINEST VARS'!$U$54+'LINEST VARS'!$T$54*($C$7)+'LINEST VARS'!$S$54*($C$8)+'LINEST VARS'!$R$54*($C$9)+'LINEST VARS'!$Q$54*($C$10)+'LINEST VARS'!$P$54*($C$11)+'LINEST VARS'!$O$54*($C$7^2)+'LINEST VARS'!$N$54*($C$8^2)+'LINEST VARS'!$M$54*($C$9^2)+'LINEST VARS'!$L$54*($C$10^2)+'LINEST VARS'!$K$54*($C$11^2)+'LINEST VARS'!$J$54*($C$7*$C$8)+'LINEST VARS'!$I$54*($C$7*$C$9)+'LINEST VARS'!$H$54*($C$7*$C$10)+'LINEST VARS'!$G$54*($C$7*$C$11)+'LINEST VARS'!$F$54*($C$8*$C$9)+'LINEST VARS'!$E$54*($C$8*$C$10)+'LINEST VARS'!$D$54*($C$8*$C$11)+'LINEST VARS'!$C$54*($C$9*$C$10)+'LINEST VARS'!$B$54*($C$9*$C$11)+'LINEST VARS'!$A$54*($C$10*$C$11) -> 4 | D19: from LINEST row 54
B20: SCz | C20: ='LINEST VARS'!$U$56+'LINEST VARS'!$T$56*($C$7)+'LINEST VARS'!$S$56*($C$8)+'LINEST VARS'!$R$56*($C$9)+'LINEST VARS'!$Q$56*($C$10)+'LINEST VARS'!$P$56*($C$11)+'LINEST VARS'!$O$56*($C$7^2)+'LINEST VARS'!$N$56*($C$8^2)+'LINEST VARS'!$M$56*($C$9^2)+'LINEST VARS'!$L$56*($C$10^2)+'LINEST VARS'!$K$56*($C$11^2)+'LINEST VARS'!$J$56*($C$7*$C$8)+'LINEST VARS'!$I$56*($C$7*$C$9)+'LINEST VARS'!$H$56*($C$7*$C$10)+'LINEST VARS'!$G$56*($C$7*$C$11)+'LINEST VARS'!$F$56*($C$8*$C$9)+'LINEST VARS'!$E$56*($C$8*$C$10)+'LINEST VARS'!$D$56*($C$8*$C$11)+'LINEST VARS'!$C$56*($C$9*$C$10)+'LINEST VARS'!$B$56*($C$9*$C$11)+'LINEST VARS'!$A$56*($C$10*$C$11) -> 2.8 | D20: from LINEST row 56
B21: SCx | C21: ='LINEST VARS'!$U$58+'LINEST VARS'!$T$58*($C$7)+'LINEST VARS'!$S$58*($C$8)+'LINEST VARS'!$R$58*($C$9)+'LINEST VARS'!$Q$58*($C$10)+'LINEST VARS'!$P$58*($C$11)+'LINEST VARS'!$O$58*($C$7^2)+'LINEST VARS'!$N$58*($C$8^2)+'LINEST VARS'!$M$58*($C$9^2)+'LINEST VARS'!$L$58*($C$10^2)+'LINEST VARS'!$K$58*($C$11^2)+'LINEST VARS'!$J$58*($C$7*$C$8)+'LINEST VARS'!$I$58*($C$7*$C$9)+'LINEST VARS'!$H$58*($C$7*$C$10)+'LINEST VARS'!$G$58*($C$7*$C$11)+'LINEST VARS'!$F$58*($C$8*$C$9)+'LINEST VARS'!$E$58*($C$8*$C$10)+'LINEST VARS'!$D$58*($C$8*$C$11)+'LINEST VARS'!$C$58*($C$9*$C$10)+'LINEST VARS'!$B$58*($C$9*$C$11)+'LINEST VARS'!$A$58*($C$10*$C$11) -> 0.8 | D21: from LINEST row 58
B22: Total Wheel Lift [lbf] | C22: ='LINEST VARS'!$U$72+'LINEST VARS'!$T$72*($C$7)+'LINEST VARS'!$S$72*($C$8)+'LINEST VARS'!$R$72*($C$9)+'LINEST VARS'!$Q$72*($C$10)+'LINEST VARS'!$P$72*($C$11)+'LINEST VARS'!$O$72*($C$7^2)+'LINEST VARS'!$N$72*($C$8^2)+'LINEST VARS'!$M$72*($C$9^2)+'LINEST VARS'!$L$72*($C$10^2)+'LINEST VARS'!$K$72*($C$11^2)+'LINEST VARS'!$J$72*($C$7*$C$8)+'LINEST VARS'!$I$72*($C$7*$C$9)+'LINEST VARS'!$H$72*($C$7*$C$10)+'LINEST VARS'!$G$72*($C$7*$C$11)+'LINEST VARS'!$F$72*($C$8*$C$9)+'LINEST VARS'!$E$72*($C$8*$C$10)+'LINEST VARS'!$D$72*($C$8*$C$11)+'LINEST VARS'!$C$72*($C$9*$C$10)+'LINEST VARS'!$B$72*($C$9*$C$11)+'LINEST VARS'!$A$72*($C$10*$C$11) -> 50 | D22: no LINEST row for this output
B23: Total Wheel Drag [lbf] | C23: ='LINEST VARS'!$U$60+'LINEST VARS'!$T$60*($C$7)+'LINEST VARS'!$S$60*($C$8)+'LINEST VARS'!$R$60*($C$9)+'LINEST VARS'!$Q$60*($C$10)+'LINEST VARS'!$P$60*($C$11)+'LINEST VARS'!$O$60*($C$7^2)+'LINEST VARS'!$N$60*($C$8^2)+'LINEST VARS'!$M$60*($C$9^2)+'LINEST VARS'!$L$60*($C$10^2)+'LINEST VARS'!$K$60*($C$11^2)+'LINEST VARS'!$J$60*($C$7*$C$8)+'LINEST VARS'!$I$60*($C$7*$C$9)+'LINEST VARS'!$H$60*($C$7*$C$10)+'LINEST VARS'!$G$60*($C$7*$C$11)+'LINEST VARS'!$F$60*($C$8*$C$9)+'LINEST VARS'!$E$60*($C$8*$C$10)+'LINEST VARS'!$D$60*($C$8*$C$11)+'LINEST VARS'!$C$60*($C$9*$C$10)+'LINEST VARS'!$B$60*($C$9*$C$11)+'LINEST VARS'!$A$60*($C$10*$C$11) -> 15 | D23: from LINEST row 60
B24: Total DF [lbf] | C24: ='LINEST VARS'!$U$62+'LINEST VARS'!$T$62*($C$7)+'LINEST VARS'!$S$62*($C$8)+'LINEST VARS'!$R$62*($C$9)+'LINEST VARS'!$Q$62*($C$10)+'LINEST VARS'!$P$62*($C$11)+'LINEST VARS'!$O$62*($C$7^2)+'LINEST VARS'!$N$62*($C$8^2)+'LINEST VARS'!$M$62*($C$9^2)+'LINEST VARS'!$L$62*($C$10^2)+'LINEST VARS'!$K$62*($C$11^2)+'LINEST VARS'!$J$62*($C$7*$C$8)+'LINEST VARS'!$I$62*($C$7*$C$9)+'LINEST VARS'!$H$62*($C$7*$C$10)+'LINEST VARS'!$G$62*($C$7*$C$11)+'LINEST VARS'!$F$62*($C$8*$C$9)+'LINEST VARS'!$E$62*($C$8*$C$10)+'LINEST VARS'!$D$62*($C$8*$C$11)+'LINEST VARS'!$C$62*($C$9*$C$10)+'LINEST VARS'!$B$62*($C$9*$C$11)+'LINEST VARS'!$A$62*($C$10*$C$11) -> 350 | D24: from LINEST row 62
B25: Total Drag [lbf] | C25: ='LINEST VARS'!$U$64+'LINEST VARS'!$T$64*($C$7)+'LINEST VARS'!$S$64*($C$8)+'LINEST VARS'!$R$64*($C$9)+'LINEST VARS'!$Q$64*($C$10)+'LINEST VARS'!$P$64*($C$11)+'LINEST VARS'!$O$64*($C$7^2)+'LINEST VARS'!$N$64*($C$8^2)+'LINEST VARS'!$M$64*($C$9^2)+'LINEST VARS'!$L$64*($C$10^2)+'LINEST VARS'!$K$64*($C$11^2)+'LINEST VARS'!$J$64*($C$7*$C$8)+'LINEST VARS'!$I$64*($C$7*$C$9)+'LINEST VARS'!$H$64*($C$7*$C$10)+'LINEST VARS'!$G$64*($C$7*$C$11)+'LINEST VARS'!$F$64*($C$8*$C$9)+'LINEST VARS'!$E$64*($C$8*$C$10)+'LINEST VARS'!$D$64*($C$8*$C$11)+'LINEST VARS'!$C$64*($C$9*$C$10)+'LINEST VARS'!$B$64*($C$9*$C$11)+'LINEST VARS'!$A$64*($C$10*$C$11) -> 110 | D25: from LINEST row 64
B26: Front Wing DF [lbf] | C26: ='LINEST VARS'!$U$66+'LINEST VARS'!$T$66*($C$7)+'LINEST VARS'!$S$66*($C$8)+'LINEST VARS'!$R$66*($C$9)+'LINEST VARS'!$Q$66*($C$10)+'LINEST VARS'!$P$66*($C$11)+'LINEST VARS'!$O$66*($C$7^2)+'LINEST VARS'!$N$66*($C$8^2)+'LINEST VARS'!$M$66*($C$9^2)+'LINEST VARS'!$L$66*($C$10^2)+'LINEST VARS'!$K$66*($C$11^2)+'LINEST VARS'!$J$66*($C$7*$C$8)+'LINEST VARS'!$I$66*($C$7*$C$9)+'LINEST VARS'!$H$66*($C$7*$C$10)+'LINEST VARS'!$G$66*($C$7*$C$11)+'LINEST VARS'!$F$66*($C$8*$C$9)+'LINEST VARS'!$E$66*($C$8*$C$10)+'LINEST VARS'!$D$66*($C$8*$C$11)+'LINEST VARS'!$C$66*($C$9*$C$10)+'LINEST VARS'!$B$66*($C$9*$C$11)+'LINEST VARS'!$A$66*($C$10*$C$11) -> 144 | D26: from LINEST row 66
B27: Undertray DF [lbf] | C27: ='LINEST VARS'!$U$68+'LINEST VARS'!$T$68*($C$7)+'LINEST VARS'!$S$68*($C$8)+'LINEST VARS'!$R$68*($C$9)+'LINEST VARS'!$Q$68*($C$10)+'LINEST VARS'!$P$68*($C$11)+'LINEST VARS'!$O$68*($C$7^2)+'LINEST VARS'!$N$68*($C$8^2)+'LINEST VARS'!$M$68*($C$9^2)+'LINEST VARS'!$L$68*($C$10^2)+'LINEST VARS'!$K$68*($C$11^2)+'LINEST VARS'!$J$68*($C$7*$C$8)+'LINEST VARS'!$I$68*($C$7*$C$9)+'LINEST VARS'!$H$68*($C$7*$C$10)+'LINEST VARS'!$G$68*($C$7*$C$11)+'LINEST VARS'!$F$68*($C$8*$C$9)+'LINEST VARS'!$E$68*($C$8*$C$10)+'LINEST VARS'!$D$68*($C$8*$C$11)+'LINEST VARS'!$C$68*($C$9*$C$10)+'LINEST VARS'!$B$68*($C$9*$C$11)+'LINEST VARS'!$A$68*($C$10*$C$11) -> 150 | D27: from LINEST row 68
B28: Rear Wing DF [lbf] | C28: ='LINEST VARS'!$U$70+'LINEST VARS'!$T$70*($C$7)+'LINEST VARS'!$S$70*($C$8)+'LINEST VARS'!$R$70*($C$9)+'LINEST VARS'!$Q$70*($C$10)+'LINEST VARS'!$P$70*($C$11)+'LINEST VARS'!$O$70*($C$7^2)+'LINEST VARS'!$N$70*($C$8^2)+'LINEST VARS'!$M$70*($C$9^2)+'LINEST VARS'!$L$70*($C$10^2)+'LINEST VARS'!$K$70*($C$11^2)+'LINEST VARS'!$J$70*($C$7*$C$8)+'LINEST VARS'!$I$70*($C$7*$C$9)+'LINEST VARS'!$H$70*($C$7*$C$10)+'LINEST VARS'!$G$70*($C$7*$C$11)+'LINEST VARS'!$F$70*($C$8*$C$9)+'LINEST VARS'!$E$70*($C$8*$C$10)+'LINEST VARS'!$D$70*($C$8*$C$11)+'LINEST VARS'!$C$70*($C$9*$C$10)+'LINEST VARS'!$B$70*($C$9*$C$11)+'LINEST VARS'!$A$70*($C$10*$C$11) -> 92 | D28: from LINEST row 70
B30: How it works: each predicted value = intercept + Σ(coefficientₖ × termₖ) using the 21-term quadratic fit on the LINEST VARS sheet.
B31: Variable convention: X1=Front Track, X2=Rear Track, X3=Yaw, X4=Roll, X5=Steer. Terms = 5 linear + 5 squared + 10 two-way interactions.
B32: Predictions are valid only INSIDE the ranges shown. Extrapolating beyond the CCD envelope will give unreliable numbers.
B33: Total Wheel Lift has no LINEST row in LINEST VARS — add a LINEST for CCD column N if you want it fitted, then point the calculator at it.

Sheet Graphs
B2: AERO RESPONSE-SURFACE HEATMAPS
B3: 21×21 grids per pairing, 12 outputs each (36 heatmaps total). Non-axis variables held at CCD center: FT=8.0, RT=8.0, Yaw=4.0, Roll=0.5, Steer=12.73. Colors are conditional formatting — green=low, yellow=mid, red=high (per grid).
B5: ━ Front Track × Rear Track (other vars at CCD center) ━ | AZ5: ━ Yaw × Roll (other vars at CCD center) ━ | CX5: ━ Yaw × Steer (other vars at CCD center) ━
B7: COP Sprung [% Front] (Front Track [in] vs Rear Track [in]) | Z7: COP Unsprung [% Front] (Front Track [in] vs Rear Track [in]) | AZ7: COP Sprung [% Front] (Yaw Angle [deg] vs Roll Angle [deg]) | BX7: COP Unsprung [% Front] (Yaw Angle [deg] vs Roll Angle [deg]) | CX7: COP Sprung [% Front] (Yaw Angle [deg] vs Steer Angle [deg]) | DV7: COP Unsprung [% Front] (Yaw Angle [deg] vs Steer Angle [deg])
B8: Rear Track [in] \ Front Track [in] | C8: 7.4 | D8: 7.46 | E8: 7.52 | F8: 7.58 | G8: 7.64 | H8: 7.7 | I8: 7.76 | J8: 7.82 | K8: 7.88 | L8: 7.94 | M8: 8 | N8: 8.06 | O8: 8.12 | P8: 8.18 | Q8: 8.24 | R8: 8.3 | S8: 8.36 | T8: 8.42 | U8: 8.48 | V8: 8.54 | W8: 8.6 | Z8: Rear Track [in] \ Front Track [in] | AA8: 7.4 | AB8: 7.46 | AC8: 7.52 | AD8: 7.58 | AE8: 7.64 | AF8: 7.7 | AG8: 7.76 | AH8: 7.82 | AI8: 7.88 | AJ8: 7.94 | AK8: 8 | AL8: 8.06 | AM8: 8.12 | AN8: 8.18 | AO8: 8.24 | AP8: 8.3 | AQ8: 8.36 | AR8: 8.42 | AS8: 8.48 | AT8: 8.54 | AU8: 8.6 | AZ8: Roll Angle [deg] \ Yaw Angle [deg] | BA8: 0 | BB8: 0.4 | BC8: 0.8 | BD8: 1.2 | BE8: 1.6 | BF8: 2 | BG8: 2.4 | BH8: 2.8 | BI8: 3.2 | BJ8: 3.6 | BK8: 4 | BL8: 4.4 | BM8: 4.8 | BN8: 5.2 | BO8: 5.6 | BP8: 6 | BQ8: 6.4 | BR8: 6.8 | BS8: 7.2 | BT8: 7.6 | BU8: 8 | BX8: Roll Angle [deg] \ Yaw Angle [deg] | BY8: 0 | BZ8: 0.4 | CA8: 0.8 | CB8: 1.2 | CC8: 1.6 | CD8: 2 | CE8: 2.4 | CF8: 2.8 | CG8: 3.2 | CH8: 3.6 | CI8: 4 | CJ8: 4.4 | CK8: 4.8 | CL8: 5.2 | CM8: 5.6 | CN8: 6 | CO8: 6.4 | CP8: 6.8 | CQ8: 7.2 | CR8: 7.6 | CS8: 8 | CX8: Steer Angle [deg] \ Yaw Angle [deg] | CY8: 0 | CZ8: 0.4 | DA8: 0.8 | DB8: 1.2 | DC8: 1.6 | DD8: 2 | DE8: 2.4 | DF8: 2.8 | DG8: 3.2 | DH8: 3.6 | DI8: 4 | DJ8: 4.4 | DK8: 4.8 | DL8: 5.2 | DM8: 5.6 | DN8: 6 | DO8: 6.4 | DP8: 6.8 | DQ8: 7.2 | DR8: 7.6 | DS8: 8 | DV8: Steer Angle [deg] \ Yaw Angle [deg] | DW8: 0 | DX8: 0.4 | DY8: 0.8 | DZ8: 1.2 | EA8: 1.6 | EB8: 2 | EC8: 2.4 | ED8: 2.8 | EE8: 3.2 | EF8: 3.6 | EG8: 4 | EH8: 4.4 | EI8: 4.8 | EJ8: 5.2 | EK8: 5.6 | EL8: 6 | EM8: 6.4 | EN8: 6.8 | EO8: 7.2 | EP8: 7.6 | EQ8: 8
